{
  "id": "EUVD-2021-0291",
  "enisaUuid": "1a2cf288-1220-3209-8e17-57ffabbc7b8c",
  "description": "TensorFlow is an end-to-end open source platform for machine learning. An attacker can cause a runtime division by zero error and denial of service in `tf.raw_ops.FractionalAvgPool`. This is because the implementation(https://github.com/tensorflow/tensorflow/blob/acc8ee69f5f46f92a3f1f11230f49c6ac266f10c/tensorflow/core/kernels/fractional_avg_pool_op.cc#L85-L89) computes a divisor quantity by dividing two user controlled values. The user controls the values of `input_size[i]` and `pooling_ratio_[i]` (via the `value.shape()` and `pooling_ratio` arguments). If the value in `input_size[i]` is smaller than the `pooling_ratio_[i]`, then the floor operation results in `output_size[i]` being 0. The `DCHECK_GT` line is a no-op outside of debug mode, so in released versions of TF this does not trigger. Later, these computed values are used as arguments(https://github.com/tensorflow/tensorflow/blob/acc8ee69f5f46f92a3f1f11230f49c6ac266f10c/tensorflow/core/kernels/fractional_avg_pool_op.cc#L96-L99) to `GeneratePoolingSequence`(https://github.com/tensorflow/tensorflow/blob/acc8ee69f5f46f92a3f1f11230f49c6ac266f10c/tensorflow/core/kernels/fractional_pool_common.cc#L100-L108). There, the first computation is a division in a modulo operation. Since `output_length` can be 0, this results in runtime crashing. The fix will be included in TensorFlow 2.5.0. We will also cherrypick this commit on TensorFlow 2.4.2, TensorFlow 2.3.3, TensorFlow 2.2.3 and TensorFlow 2.1.4, as these are also affected and still in supported range.",
  "datePublished": "May 14, 2021, 8:15:00 PM",
  "dateUpdated": "Aug 27, 2021, 3:22:30 AM",
  "baseScore": 2.5,
  "baseScoreVersion": "3.1",
  "baseScoreVector": "CVSS:3.1/AV:L/AC:H/PR:L/UI:N/S:U/C:N/I:N/A:L",
  "references": [
    "https://github.com/tensorflow/tensorflow/security/advisories/GHSA-f78g-q7r4-9wcv",
    "https://github.com/tensorflow/tensorflow/commit/548b5eaf23685d86f722233d8fbc21d0a4aecb96",
    "https://nvd.nist.gov/vuln/detail/CVE-2021-29550",
    "https://github.com/pypa/advisory-database/tree/main/vulns/tensorflow-cpu/PYSEC-2021-478.yaml",
    "https://github.com/pypa/advisory-database/tree/main/vulns/tensorflow-gpu/PYSEC-2021-676.yaml",
    "https://github.com/pypa/advisory-database/tree/main/vulns/tensorflow/PYSEC-2021-187.yaml",
    "https://www.suse.com/security/cve/CVE-2021-29550.html",
    "https://security.archlinux.org/CVE-2021-29550"
  ],
  "aliases": [
    "CVE-2021-29550",
    "GHSA-f78g-q7r4-9wcv",
    "PYSEC-2021-478"
  ],
  "assigner": "GitHub_M",
  "epss": 0.02,
  "enisaIdProduct": [
    {
      "id": "6f08d5ca-fb9b-3bf2-9d20-4bc7e46fc8cd",
      "product": {
        "name": "tensorflow"
      },
      "product_version": "2.2.0, < 2.2.3"
    },
    {
      "id": "70812ae2-e1cc-3dcb-8bb5-eb0af032a31c",
      "product": {
        "name": "tensorflow"
      },
      "product_version": "2.4.0, < 2.4.2"
    },
    {
      "id": "739793fc-8e01-34eb-893a-60922deb0099",
      "product": {
        "name": "tensorflow"
      },
      "product_version": "2.3.0, < 2.3.3"
    },
    {
      "id": "c28abb0b-64ba-3c04-93de-f2a2dae53db5",
      "product": {
        "name": "tensorflow"
      },
      "product_version": "< 2.1.4"
    }
  ],
  "enisaIdVendor": [
    {
      "id": "9a019f28-1dd0-3153-b5b0-222bbe1c825e",
      "vendor": {
        "name": "tensorflow"
      }
    }
  ]
}