{
  "id": "EUVD-2021-1519",
  "enisaUuid": "803e5538-e340-35d4-856c-9a190ea481d4",
  "description": "An issue was discovered in the pyo3 crate before 0.12.4 for Rust. There is a reference-counting error and use-after-free in From<Py<T>>.",
  "datePublished": "Dec 31, 2020, 8:18:37 AM",
  "dateUpdated": "Aug 4, 2024, 5:16:13 PM",
  "baseScore": 5.5,
  "baseScoreVersion": "3.1",
  "baseScoreVector": "CVSS:3.1/AV:L/AC:L/PR:L/UI:N/S:U/C:N/I:N/A:H",
  "references": [
    "https://nvd.nist.gov/vuln/detail/CVE-2020-35917",
    "https://github.com/PyO3/pyo3/pull/1297",
    "https://github.com/PyO3/pyo3/commit/8f81f595dd770b586c7ca7195b42004a6c976eb9",
    "https://github.com/PyO3/pyo3",
    "https://rustsec.org/advisories/RUSTSEC-2020-0074.html"
  ],
  "aliases": [
    "CVE-2020-35917",
    "GHSA-2vx6-fcw6-hpr6"
  ],
  "assigner": "mitre",
  "epss": 0.06,
  "enisaIdProduct": [
    {
      "id": "737c1a0a-d2b6-35da-a63e-a2a4660824b3",
      "product": {
        "name": "n/a"
      },
      "product_version": "n/a"
    }
  ],
  "enisaIdVendor": [
    {
      "id": "7540b0eb-ea50-3f8a-83ab-1aff23f2d80c",
      "vendor": {
        "name": "n/a"
      }
    }
  ]
}