{
  "id": "EUVD-2025-0001",
  "enisaUuid": "1476bba1-5e2b-312f-b5fc-18d18c42c467",
  "description": "Django has a potential denial-of-service vulnerability in IPv6 validation",
  "datePublished": "Jan 14, 2025, 9:31:47 PM",
  "dateUpdated": "May 20, 2025, 6:06:45 PM",
  "baseScore": 5.8,
  "baseScoreVersion": "3.1",
  "baseScoreVector": "CVSS:3.1/AV:N/AC:L/PR:N/UI:N/S:C/C:N/I:N/A:L",
  "references": [
    "https://www.djangoproject.com/weblog/2025/jan/14/security-releases/",
    "https://docs.djangoproject.com/en/dev/releases/security/",
    "https://groups.google.com/g/django-announce",
    "http://www.openwall.com/lists/oss-security/2025/01/14/2",
    "https://nvd.nist.gov/vuln/detail/CVE-2024-56374",
    "https://github.com/django/django/commit/ca2be7724e1244a4cb723de40a070f873c6e94bf",
    "https://github.com/pypa/advisory-database/tree/main/vulns/django/PYSEC-2025-1.yaml",
    "https://lists.debian.org/debian-lts-announce/2025/01/msg00024.html",
    "https://github.com/django/django/commit/4806731e58f3e8700a3c802e77899d54ac6021fe",
    "https://github.com/django/django/commit/ad866a1ca3e7d60da888d25d27e46a8adb2ed36e",
    "https://github.com/django/django/commit/e8d4a2005955dcf962193600b53bf461b190b455"
  ],
  "aliases": [
    "CVE-2024-56374",
    "PYSEC-2025-1"
  ],
  "assigner": "mitre",
  "epss": 0.3,
  "enisaIdProduct": [
    {
      "id": "b43dc513-bfde-3923-b42a-51e4d0741724",
      "product": {
        "name": "Django"
      },
      "product_version": "5.1 <5.1.5"
    },
    {
      "id": "dc259867-0528-368b-8786-e0708be8360f",
      "product": {
        "name": "Django"
      },
      "product_version": "4.2 <4.2.18"
    },
    {
      "id": "e4c41bcf-92a0-3432-a30c-e6281f1aa956",
      "product": {
        "name": "Django"
      },
      "product_version": "5.0 <5.0.11"
    }
  ],
  "enisaIdVendor": [
    {
      "id": "0a160edd-acac-30a6-b7e9-5d924fe04066",
      "vendor": {
        "name": "djangoproject"
      }
    }
  ]
}